Shutting Down Docker Instance
DOCKER INSTANCE IS DOWN
2021-09-13-11:00:01 PM - [BART-Loglevel4] Starting backup
2021-09-13-11:00:01 PM - [BART-Loglevel4] Set script variables done

2021-09-13-11:00:01 PM - [BART-Loglevel4] Backing up the Alfresco indexes to local
2021-09-13-11:00:01 PM - [BART-Loglevel4] Starting backup - Alfresco solr indexes
2021-09-13-11:00:01 PM - [BART-Loglevel4] Running command - /usr/bin/duplicity -v4 --volsize=20000 --log-file=/var/ALF_BACKUP/cardinal/logs/alfresco-bart-2021-09-13.log --full-if-older-than 60D --asynchronous-upload --archive-dir=/var/ALF_BACKUP/duplicity/cardinal/cache/  /var/DOCKER/DATA/alfresco/cardinal/solr_data --exclude /var/DOCKER/DATA/alfresco/cardinal/solr_data/archive --exclude /var/DOCKER/DATA/alfresco/cardinal/solr_data/workspace file:///var/BACKUPS/ALF_BACKUP/cardinal/data_backup/index/config
Local and Remote metadata are synchronized, no sync needed.
NOTICE 1
. Local and Remote metadata are synchronized, no sync needed.

ERROR 30 IOError
. Traceback (most recent call last):
.   File "/usr/bin/duplicity", line 1553, in <module>
.     with_tempdir(main)
.   File "/usr/bin/duplicity", line 1547, in with_tempdir
.     fn()
.   File "/usr/bin/duplicity", line 1398, in main
.     do_backup(action)
.   File "/usr/bin/duplicity", line 1423, in do_backup
.     globals.archive_dir).set_values()
.   File "/usr/lib/python2.7/dist-packages/duplicity/collections.py", line 710, in set_values
.     self.get_backup_chains(partials + backend_filename_list)
.   File "/usr/lib/python2.7/dist-packages/duplicity/collections.py", line 836, in get_backup_chains
.     add_to_sets(f)
.   File "/usr/lib/python2.7/dist-packages/duplicity/collections.py", line 830, in add_to_sets
.     if new_set.add_filename(filename):
.   File "/usr/lib/python2.7/dist-packages/duplicity/collections.py", line 101, in add_filename
.     self.set_manifest(filename)
.   File "/usr/lib/python2.7/dist-packages/duplicity/collections.py", line 148, in set_manifest
.     self.set_files_changed()
.   File "/usr/lib/python2.7/dist-packages/duplicity/collections.py", line 128, in set_files_changed
.     mf = self.get_manifest()
.   File "/usr/lib/python2.7/dist-packages/duplicity/collections.py", line 250, in get_manifest
.     return self.get_local_manifest()
.   File "/usr/lib/python2.7/dist-packages/duplicity/collections.py", line 222, in get_local_manifest
.     manifest_buffer = self.local_manifest_path.get_data()
.   File "/usr/lib/python2.7/dist-packages/duplicity/path.py", line 178, in get_data
.     fin = self.open("rb")
.   File "/usr/lib/python2.7/dist-packages/duplicity/path.py", line 566, in open
.     result = open(self.name, mode)
. IOError: [Errno 13] Permission denied: '/var/ALF_BACKUP/duplicity/cardinal/cache/fb357b7251c71dad80d73e356adca2d4/duplicity-inc.20210908T230002Z.to.20210909T230001Z.manifest'
. 

2021-09-13-11:00:01 PM - [BART-Loglevel4] Indexes backup finished

2021-09-13-11:00:01 PM - [BART-Loglevel4] Backing up the Alfresco db to local
2021-09-13-11:00:01 PM - [BART-Loglevel4] Starting backup - Alfresco postgresql db
2021-09-13-11:00:01 PM - [BART-Loglevel4] Backing up the Alfresco DB to local
2021-09-13-11:00:01 PM - [BART-Loglevel4] Starting backup - Alfresco postgresql DB
2021-09-13-11:00:01 PM - [BART-Loglevel4] Running command - PGPASSWORD=45osUQR234X /usr/lib/postgresql/11/bin/pg_dump -Fc -w -h 172.18.200.70 -p 5000 -U alfresco alf_cardinal > /var/ALF_BACKUP/cardinal/alfresco-db-backup/alf_cardinal.sql.Fc
2021-09-13-11:00:41 PM - [BART-Loglevel4] Running command - duplicity -v4 --volsize=20000 --log-file=/var/ALF_BACKUP/cardinal/logs/alfresco-bart-2021-09-13.log --full-if-older-than 60D --asynchronous-upload --archive-dir=/var/ALF_BACKUP/duplicity/cardinal/cache/  /var/ALF_BACKUP/cardinal/alfresco-db-backup file:///var/BACKUPS/ALF_BACKUP/cardinal/data_backup/db
Local and Remote metadata are synchronized, no sync needed.
NOTICE 1
. Local and Remote metadata are synchronized, no sync needed.

ERROR 30 IOError
. Traceback (most recent call last):
.   File "/usr/bin/duplicity", line 1553, in <module>
.     with_tempdir(main)
.   File "/usr/bin/duplicity", line 1547, in with_tempdir
.     fn()
.   File "/usr/bin/duplicity", line 1398, in main
.     do_backup(action)
.   File "/usr/bin/duplicity", line 1423, in do_backup
.     globals.archive_dir).set_values()
.   File "/usr/lib/python2.7/dist-packages/duplicity/collections.py", line 710, in set_values
.     self.get_backup_chains(partials + backend_filename_list)
.   File "/usr/lib/python2.7/dist-packages/duplicity/collections.py", line 836, in get_backup_chains
.     add_to_sets(f)
.   File "/usr/lib/python2.7/dist-packages/duplicity/collections.py", line 830, in add_to_sets
.     if new_set.add_filename(filename):
.   File "/usr/lib/python2.7/dist-packages/duplicity/collections.py", line 101, in add_filename
.     self.set_manifest(filename)
.   File "/usr/lib/python2.7/dist-packages/duplicity/collections.py", line 148, in set_manifest
.     self.set_files_changed()
.   File "/usr/lib/python2.7/dist-packages/duplicity/collections.py", line 128, in set_files_changed
.     mf = self.get_manifest()
.   File "/usr/lib/python2.7/dist-packages/duplicity/collections.py", line 250, in get_manifest
.     return self.get_local_manifest()
.   File "/usr/lib/python2.7/dist-packages/duplicity/collections.py", line 222, in get_local_manifest
.     manifest_buffer = self.local_manifest_path.get_data()
.   File "/usr/lib/python2.7/dist-packages/duplicity/path.py", line 178, in get_data
.     fin = self.open("rb")
.   File "/usr/lib/python2.7/dist-packages/duplicity/path.py", line 566, in open
.     result = open(self.name, mode)
. IOError: [Errno 13] Permission denied: '/var/ALF_BACKUP/duplicity/cardinal/cache/851ae8022a8438d2a54208d38005896b/duplicity-inc.20210908T230004Z.to.20210908T230037Z.manifest'
. 

2021-09-13-11:00:41 PM - [BART-Loglevel4] cleaning DB backup
2021-09-13-11:00:41 PM - [BART-Loglevel4] DB backup finished

2021-09-13-11:00:41 PM - [BART-Loglevel4] Backing up the Alfresco ContentStore to local
2021-09-13-11:00:41 PM - [BART-Loglevel4] Starting backup - Alfresco ContentStore
2021-09-13-11:00:41 PM - [BART-Loglevel4] Running command - /usr/bin/duplicity -v4 --volsize=20000 --log-file=/var/ALF_BACKUP/cardinal/logs/alfresco-bart-2021-09-13.log --full-if-older-than 60D --asynchronous-upload --archive-dir=/var/ALF_BACKUP/duplicity/cardinal/cache/  --include /var/DOCKER/DATA/alfresco/cardinal/alfresco/alf_data_archgroup/contentstore       --exclude /var/DOCKER/DATA/alfresco/cardinal/alfresco/alf_data_archgroup /var/DOCKER/DATA/alfresco/cardinal/alfresco/alf_data_archgroup file:///var/BACKUPS/ALF_BACKUP/cardinal/data_backup/cs
Local and Remote metadata are synchronized, no sync needed.
NOTICE 1
. Local and Remote metadata are synchronized, no sync needed.

Last full backup date: Fri Aug  6 16:23:14 2021
NOTICE 1
. Last full backup date: Fri Aug  6 16:23:14 2021

Error accessing possibly locked file /var/DOCKER/DATA/alfresco/cardinal/alfresco/alf_data_archgroup/contentstore/2021/1/22/22
WARNING 10 '/var/DOCKER/DATA/alfresco/cardinal/alfresco/alf_data_archgroup/contentstore/2021/1/22/22'
. Error accessing possibly locked file /var/DOCKER/DATA/alfresco/cardinal/alfresco/alf_data_archgroup/contentstore/2021/1/22/22

Error accessing possibly locked file /var/DOCKER/DATA/alfresco/cardinal/alfresco/alf_data_archgroup/contentstore/2021/1/23
WARNING 10 '/var/DOCKER/DATA/alfresco/cardinal/alfresco/alf_data_archgroup/contentstore/2021/1/23'
. Error accessing possibly locked file /var/DOCKER/DATA/alfresco/cardinal/alfresco/alf_data_archgroup/contentstore/2021/1/23

Error accessing possibly locked file /var/DOCKER/DATA/alfresco/cardinal/alfresco/alf_data_archgroup/contentstore/2021/1/25
WARNING 10 '/var/DOCKER/DATA/alfresco/cardinal/alfresco/alf_data_archgroup/contentstore/2021/1/25'
. Error accessing possibly locked file /var/DOCKER/DATA/alfresco/cardinal/alfresco/alf_data_archgroup/contentstore/2021/1/25

Error accessing possibly locked file /var/DOCKER/DATA/alfresco/cardinal/alfresco/alf_data_archgroup/contentstore/2021/1/26
WARNING 10 '/var/DOCKER/DATA/alfresco/cardinal/alfresco/alf_data_archgroup/contentstore/2021/1/26'
. Error accessing possibly locked file /var/DOCKER/DATA/alfresco/cardinal/alfresco/alf_data_archgroup/contentstore/2021/1/26

Error accessing possibly locked file /var/DOCKER/DATA/alfresco/cardinal/alfresco/alf_data_archgroup/contentstore/2021/1/27
WARNING 10 '/var/DOCKER/DATA/alfresco/cardinal/alfresco/alf_data_archgroup/contentstore/2021/1/27'
. Error accessing possibly locked file /var/DOCKER/DATA/alfresco/cardinal/alfresco/alf_data_archgroup/contentstore/2021/1/27

Error accessing possibly locked file /var/DOCKER/DATA/alfresco/cardinal/alfresco/alf_data_archgroup/contentstore/2021/1/28
WARNING 10 '/var/DOCKER/DATA/alfresco/cardinal/alfresco/alf_data_archgroup/contentstore/2021/1/28'
. Error accessing possibly locked file /var/DOCKER/DATA/alfresco/cardinal/alfresco/alf_data_archgroup/contentstore/2021/1/28

Error accessing possibly locked file /var/DOCKER/DATA/alfresco/cardinal/alfresco/alf_data_archgroup/contentstore/2021/1/29
WARNING 10 '/var/DOCKER/DATA/alfresco/cardinal/alfresco/alf_data_archgroup/contentstore/2021/1/29'
. Error accessing possibly locked file /var/DOCKER/DATA/alfresco/cardinal/alfresco/alf_data_archgroup/contentstore/2021/1/29

Error accessing possibly locked file /var/DOCKER/DATA/alfresco/cardinal/alfresco/alf_data_archgroup/contentstore/2021/1/30
WARNING 10 '/var/DOCKER/DATA/alfresco/cardinal/alfresco/alf_data_archgroup/contentstore/2021/1/30'
. Error accessing possibly locked file /var/DOCKER/DATA/alfresco/cardinal/alfresco/alf_data_archgroup/contentstore/2021/1/30

Error accessing possibly locked file /var/DOCKER/DATA/alfresco/cardinal/alfresco/alf_data_archgroup/contentstore/2021/2
WARNING 10 '/var/DOCKER/DATA/alfresco/cardinal/alfresco/alf_data_archgroup/contentstore/2021/2'
. Error accessing possibly locked file /var/DOCKER/DATA/alfresco/cardinal/alfresco/alf_data_archgroup/contentstore/2021/2

Error accessing possibly locked file /var/DOCKER/DATA/alfresco/cardinal/alfresco/alf_data_archgroup/contentstore/2021/3
WARNING 10 '/var/DOCKER/DATA/alfresco/cardinal/alfresco/alf_data_archgroup/contentstore/2021/3'
. Error accessing possibly locked file /var/DOCKER/DATA/alfresco/cardinal/alfresco/alf_data_archgroup/contentstore/2021/3

Error accessing possibly locked file /var/DOCKER/DATA/alfresco/cardinal/alfresco/alf_data_archgroup/contentstore/2021/4
WARNING 10 '/var/DOCKER/DATA/alfresco/cardinal/alfresco/alf_data_archgroup/contentstore/2021/4'
. Error accessing possibly locked file /var/DOCKER/DATA/alfresco/cardinal/alfresco/alf_data_archgroup/contentstore/2021/4

Error accessing possibly locked file /var/DOCKER/DATA/alfresco/cardinal/alfresco/alf_data_archgroup/contentstore/2021/5
WARNING 10 '/var/DOCKER/DATA/alfresco/cardinal/alfresco/alf_data_archgroup/contentstore/2021/5'
. Error accessing possibly locked file /var/DOCKER/DATA/alfresco/cardinal/alfresco/alf_data_archgroup/contentstore/2021/5

Error accessing possibly locked file /var/DOCKER/DATA/alfresco/cardinal/alfresco/alf_data_archgroup/contentstore/2021/6
WARNING 10 '/var/DOCKER/DATA/alfresco/cardinal/alfresco/alf_data_archgroup/contentstore/2021/6'
. Error accessing possibly locked file /var/DOCKER/DATA/alfresco/cardinal/alfresco/alf_data_archgroup/contentstore/2021/6

Error accessing possibly locked file /var/DOCKER/DATA/alfresco/cardinal/alfresco/alf_data_archgroup/contentstore/2021/7
WARNING 10 '/var/DOCKER/DATA/alfresco/cardinal/alfresco/alf_data_archgroup/contentstore/2021/7'
. Error accessing possibly locked file /var/DOCKER/DATA/alfresco/cardinal/alfresco/alf_data_archgroup/contentstore/2021/7

Error accessing possibly locked file /var/DOCKER/DATA/alfresco/cardinal/alfresco/alf_data_archgroup/contentstore/2021/8
WARNING 10 '/var/DOCKER/DATA/alfresco/cardinal/alfresco/alf_data_archgroup/contentstore/2021/8'
. Error accessing possibly locked file /var/DOCKER/DATA/alfresco/cardinal/alfresco/alf_data_archgroup/contentstore/2021/8

Error accessing possibly locked file /var/DOCKER/DATA/alfresco/cardinal/alfresco/alf_data_archgroup/contentstore/2021/9
WARNING 10 '/var/DOCKER/DATA/alfresco/cardinal/alfresco/alf_data_archgroup/contentstore/2021/9'
. Error accessing possibly locked file /var/DOCKER/DATA/alfresco/cardinal/alfresco/alf_data_archgroup/contentstore/2021/9

--------------[ Backup Statistics ]--------------
StartTime 1631574043.77 (Mon Sep 13 23:00:43 2021)
EndTime 1631574150.19 (Mon Sep 13 23:02:30 2021)
ElapsedTime 106.42 (1 minute 46.42 seconds)
SourceFiles 295430
SourceFileSize 125411282665 (117 GB)
NewFiles 0
NewFileSize 0 (0 bytes)
DeletedFiles 0
ChangedFiles 0
ChangedFileSize 0 (0 bytes)
ChangedDeltaSize 0 (0 bytes)
DeltaEntries 0
RawDeltaSize 0 (0 bytes)
TotalDestinationSizeChange 111 (111 bytes)
Errors 16
-------------------------------------------------

NOTICE 1
. --------------[ Backup Statistics ]--------------
. StartTime 1631574043.77 (Mon Sep 13 23:00:43 2021)
. EndTime 1631574150.19 (Mon Sep 13 23:02:30 2021)
. ElapsedTime 106.42 (1 minute 46.42 seconds)
. SourceFiles 295430
. SourceFileSize 125411282665 (117 GB)
. NewFiles 0
. NewFileSize 0 (0 bytes)
. DeletedFiles 0
. ChangedFiles 0
. ChangedFileSize 0 (0 bytes)
. ChangedDeltaSize 0 (0 bytes)
. DeltaEntries 0
. RawDeltaSize 0 (0 bytes)
. TotalDestinationSizeChange 111 (111 bytes)
. Errors 16
. -------------------------------------------------
. 

2021-09-13-11:02:30 PM - [BART-Loglevel4] ContentStore backup done!

2021-09-13-11:02:30 PM - [BART-Loglevel4] Backing up the Alfresco files to local
2021-09-13-11:02:30 PM - [BART-Loglevel4] Starting backup - Alfresco files
2021-09-13-11:02:30 PM - [BART-Loglevel4] Running command - /usr/bin/duplicity -v4 --volsize=20000 --log-file=/var/ALF_BACKUP/cardinal/logs/alfresco-bart-2021-09-13.log --full-if-older-than 60D --asynchronous-upload --archive-dir=/var/ALF_BACKUP/duplicity/cardinal/cache/  /var/DOCKER/DATA/alfresco/cardinal/alfresco  --exclude **/var/DOCKER/DATA/alfresco/cardinal/solr_data/archive**  --exclude **/var/DOCKER/DATA/alfresco/cardinal/solr_data**  --exclude **/var/DOCKER/DATA/alfresco/cardinal/alfresco/alf_data_archgroup/contentstore**  --exclude **/var/DOCKER/DATA/alfresco/cardinal/alfresco/alf_data_archgroup/contentstore.deleted**       --exclude **/var/ALF_BACKUP/cardinal/alfresco-db-backup**  file:///var/BACKUPS/ALF_BACKUP/cardinal/data_backup/files
Local and Remote metadata are synchronized, no sync needed.
NOTICE 1
. Local and Remote metadata are synchronized, no sync needed.

ERROR 30 IOError
. Traceback (most recent call last):
.   File "/usr/bin/duplicity", line 1553, in <module>
.     with_tempdir(main)
.   File "/usr/bin/duplicity", line 1547, in with_tempdir
.     fn()
.   File "/usr/bin/duplicity", line 1398, in main
.     do_backup(action)
.   File "/usr/bin/duplicity", line 1423, in do_backup
.     globals.archive_dir).set_values()
.   File "/usr/lib/python2.7/dist-packages/duplicity/collections.py", line 710, in set_values
.     self.get_backup_chains(partials + backend_filename_list)
.   File "/usr/lib/python2.7/dist-packages/duplicity/collections.py", line 836, in get_backup_chains
.     add_to_sets(f)
.   File "/usr/lib/python2.7/dist-packages/duplicity/collections.py", line 824, in add_to_sets
.     if set.add_filename(filename):
.   File "/usr/lib/python2.7/dist-packages/duplicity/collections.py", line 101, in add_filename
.     self.set_manifest(filename)
.   File "/usr/lib/python2.7/dist-packages/duplicity/collections.py", line 148, in set_manifest
.     self.set_files_changed()
.   File "/usr/lib/python2.7/dist-packages/duplicity/collections.py", line 128, in set_files_changed
.     mf = self.get_manifest()
.   File "/usr/lib/python2.7/dist-packages/duplicity/collections.py", line 250, in get_manifest
.     return self.get_local_manifest()
.   File "/usr/lib/python2.7/dist-packages/duplicity/collections.py", line 222, in get_local_manifest
.     manifest_buffer = self.local_manifest_path.get_data()
.   File "/usr/lib/python2.7/dist-packages/duplicity/path.py", line 178, in get_data
.     fin = self.open("rb")
.   File "/usr/lib/python2.7/dist-packages/duplicity/path.py", line 566, in open
.     result = open(self.name, mode)
. IOError: [Errno 13] Permission denied: '/var/ALF_BACKUP/duplicity/cardinal/cache/8631ebd4b7614287d4db1bbfe9c47d1d/duplicity-inc.20210907T230228Z.to.20210908T230040Z.manifest'
. 

2021-09-13-11:02:32 PM - [BART-Loglevel4] Files backup done!

2021-09-13-11:02:32 PM - [BART-Loglevel4] Running maintenance commands
2021-09-13-11:02:32 PM - [BART-Loglevel4] Running command - /usr/bin/duplicity remove-older-than 12M -v4 --log-file=/var/ALF_BACKUP/cardinal/logs/alfresco-bart-2021-09-13.log --archive-dir=/var/ALF_BACKUP/duplicity/cardinal/cache/ --force file:///var/BACKUPS/ALF_BACKUP/cardinal/data_backup/index/backup
Local and Remote metadata are synchronized, no sync needed.
NOTICE 1
. Local and Remote metadata are synchronized, no sync needed.

Last full backup date: none
NOTICE 1
. Last full backup date: none

No old backup sets found, nothing deleted.
NOTICE 1
. No old backup sets found, nothing deleted.

2021-09-13-11:02:33 PM - [BART-Loglevel4] Running command - /usr/bin/duplicity remove-all-but-n-full 6 -v4 --log-file=/var/ALF_BACKUP/cardinal/logs/alfresco-bart-2021-09-13.log --archive-dir=/var/ALF_BACKUP/duplicity/cardinal/cache/ --force file:///var/BACKUPS/ALF_BACKUP/cardinal/data_backup/index/backup
Local and Remote metadata are synchronized, no sync needed.
NOTICE 1
. Local and Remote metadata are synchronized, no sync needed.

Last full backup date: none
NOTICE 1
. Last full backup date: none

No old backup sets found, nothing deleted.
NOTICE 1
. No old backup sets found, nothing deleted.

Local and Remote metadata are synchronized, no sync needed.
NOTICE 1
. Local and Remote metadata are synchronized, no sync needed.

ERROR 30 IOError
. Traceback (most recent call last):
.   File "/usr/bin/duplicity", line 1553, in <module>
.     with_tempdir(main)
.   File "/usr/bin/duplicity", line 1547, in with_tempdir
.     fn()
.   File "/usr/bin/duplicity", line 1398, in main
.     do_backup(action)
.   File "/usr/bin/duplicity", line 1423, in do_backup
.     globals.archive_dir).set_values()
.   File "/usr/lib/python2.7/dist-packages/duplicity/collections.py", line 710, in set_values
.     self.get_backup_chains(partials + backend_filename_list)
.   File "/usr/lib/python2.7/dist-packages/duplicity/collections.py", line 836, in get_backup_chains
.     add_to_sets(f)
.   File "/usr/lib/python2.7/dist-packages/duplicity/collections.py", line 830, in add_to_sets
.     if new_set.add_filename(filename):
.   File "/usr/lib/python2.7/dist-packages/duplicity/collections.py", line 101, in add_filename
.     self.set_manifest(filename)
.   File "/usr/lib/python2.7/dist-packages/duplicity/collections.py", line 148, in set_manifest
.     self.set_files_changed()
.   File "/usr/lib/python2.7/dist-packages/duplicity/collections.py", line 128, in set_files_changed
.     mf = self.get_manifest()
.   File "/usr/lib/python2.7/dist-packages/duplicity/collections.py", line 250, in get_manifest
.     return self.get_local_manifest()
.   File "/usr/lib/python2.7/dist-packages/duplicity/collections.py", line 222, in get_local_manifest
.     manifest_buffer = self.local_manifest_path.get_data()
.   File "/usr/lib/python2.7/dist-packages/duplicity/path.py", line 178, in get_data
.     fin = self.open("rb")
.   File "/usr/lib/python2.7/dist-packages/duplicity/path.py", line 566, in open
.     result = open(self.name, mode)
. IOError: [Errno 13] Permission denied: '/var/ALF_BACKUP/duplicity/cardinal/cache/fb357b7251c71dad80d73e356adca2d4/duplicity-inc.20210908T230002Z.to.20210909T230001Z.manifest'
. 

Local and Remote metadata are synchronized, no sync needed.
NOTICE 1
. Local and Remote metadata are synchronized, no sync needed.

ERROR 30 IOError
. Traceback (most recent call last):
.   File "/usr/bin/duplicity", line 1553, in <module>
.     with_tempdir(main)
.   File "/usr/bin/duplicity", line 1547, in with_tempdir
.     fn()
.   File "/usr/bin/duplicity", line 1398, in main
.     do_backup(action)
.   File "/usr/bin/duplicity", line 1423, in do_backup
.     globals.archive_dir).set_values()
.   File "/usr/lib/python2.7/dist-packages/duplicity/collections.py", line 710, in set_values
.     self.get_backup_chains(partials + backend_filename_list)
.   File "/usr/lib/python2.7/dist-packages/duplicity/collections.py", line 836, in get_backup_chains
.     add_to_sets(f)
.   File "/usr/lib/python2.7/dist-packages/duplicity/collections.py", line 830, in add_to_sets
.     if new_set.add_filename(filename):
.   File "/usr/lib/python2.7/dist-packages/duplicity/collections.py", line 101, in add_filename
.     self.set_manifest(filename)
.   File "/usr/lib/python2.7/dist-packages/duplicity/collections.py", line 148, in set_manifest
.     self.set_files_changed()
.   File "/usr/lib/python2.7/dist-packages/duplicity/collections.py", line 128, in set_files_changed
.     mf = self.get_manifest()
.   File "/usr/lib/python2.7/dist-packages/duplicity/collections.py", line 250, in get_manifest
.     return self.get_local_manifest()
.   File "/usr/lib/python2.7/dist-packages/duplicity/collections.py", line 222, in get_local_manifest
.     manifest_buffer = self.local_manifest_path.get_data()
.   File "/usr/lib/python2.7/dist-packages/duplicity/path.py", line 178, in get_data
.     fin = self.open("rb")
.   File "/usr/lib/python2.7/dist-packages/duplicity/path.py", line 566, in open
.     result = open(self.name, mode)
. IOError: [Errno 13] Permission denied: '/var/ALF_BACKUP/duplicity/cardinal/cache/fb357b7251c71dad80d73e356adca2d4/duplicity-inc.20210908T230002Z.to.20210909T230001Z.manifest'
. 

2021-09-13-11:02:33 PM - [BART-Loglevel4] Running command - /usr/bin/duplicity remove-older-than 12M -v4 --log-file=/var/ALF_BACKUP/cardinal/logs/alfresco-bart-2021-09-13.log --archive-dir=/var/ALF_BACKUP/duplicity/cardinal/cache/ --force file:///var/BACKUPS/ALF_BACKUP/cardinal/data_backup/db
Local and Remote metadata are synchronized, no sync needed.
NOTICE 1
. Local and Remote metadata are synchronized, no sync needed.

ERROR 30 IOError
. Traceback (most recent call last):
.   File "/usr/bin/duplicity", line 1553, in <module>
.     with_tempdir(main)
.   File "/usr/bin/duplicity", line 1547, in with_tempdir
.     fn()
.   File "/usr/bin/duplicity", line 1398, in main
.     do_backup(action)
.   File "/usr/bin/duplicity", line 1423, in do_backup
.     globals.archive_dir).set_values()
.   File "/usr/lib/python2.7/dist-packages/duplicity/collections.py", line 710, in set_values
.     self.get_backup_chains(partials + backend_filename_list)
.   File "/usr/lib/python2.7/dist-packages/duplicity/collections.py", line 836, in get_backup_chains
.     add_to_sets(f)
.   File "/usr/lib/python2.7/dist-packages/duplicity/collections.py", line 830, in add_to_sets
.     if new_set.add_filename(filename):
.   File "/usr/lib/python2.7/dist-packages/duplicity/collections.py", line 101, in add_filename
.     self.set_manifest(filename)
.   File "/usr/lib/python2.7/dist-packages/duplicity/collections.py", line 148, in set_manifest
.     self.set_files_changed()
.   File "/usr/lib/python2.7/dist-packages/duplicity/collections.py", line 128, in set_files_changed
.     mf = self.get_manifest()
.   File "/usr/lib/python2.7/dist-packages/duplicity/collections.py", line 250, in get_manifest
.     return self.get_local_manifest()
.   File "/usr/lib/python2.7/dist-packages/duplicity/collections.py", line 222, in get_local_manifest
.     manifest_buffer = self.local_manifest_path.get_data()
.   File "/usr/lib/python2.7/dist-packages/duplicity/path.py", line 178, in get_data
.     fin = self.open("rb")
.   File "/usr/lib/python2.7/dist-packages/duplicity/path.py", line 566, in open
.     result = open(self.name, mode)
. IOError: [Errno 13] Permission denied: '/var/ALF_BACKUP/duplicity/cardinal/cache/851ae8022a8438d2a54208d38005896b/duplicity-inc.20210908T230004Z.to.20210908T230037Z.manifest'
. 

2021-09-13-11:02:33 PM - [BART-Loglevel4] Running command - /usr/bin/duplicity remove-all-but-n-full 6 -v4 --log-file=/var/ALF_BACKUP/cardinal/logs/alfresco-bart-2021-09-13.log --archive-dir=/var/ALF_BACKUP/duplicity/cardinal/cache/ --force file:///var/BACKUPS/ALF_BACKUP/cardinal/data_backup/db
Local and Remote metadata are synchronized, no sync needed.
NOTICE 1
. Local and Remote metadata are synchronized, no sync needed.

ERROR 30 IOError
. Traceback (most recent call last):
.   File "/usr/bin/duplicity", line 1553, in <module>
.     with_tempdir(main)
.   File "/usr/bin/duplicity", line 1547, in with_tempdir
.     fn()
.   File "/usr/bin/duplicity", line 1398, in main
.     do_backup(action)
.   File "/usr/bin/duplicity", line 1423, in do_backup
.     globals.archive_dir).set_values()
.   File "/usr/lib/python2.7/dist-packages/duplicity/collections.py", line 710, in set_values
.     self.get_backup_chains(partials + backend_filename_list)
.   File "/usr/lib/python2.7/dist-packages/duplicity/collections.py", line 836, in get_backup_chains
.     add_to_sets(f)
.   File "/usr/lib/python2.7/dist-packages/duplicity/collections.py", line 830, in add_to_sets
.     if new_set.add_filename(filename):
.   File "/usr/lib/python2.7/dist-packages/duplicity/collections.py", line 101, in add_filename
.     self.set_manifest(filename)
.   File "/usr/lib/python2.7/dist-packages/duplicity/collections.py", line 148, in set_manifest
.     self.set_files_changed()
.   File "/usr/lib/python2.7/dist-packages/duplicity/collections.py", line 128, in set_files_changed
.     mf = self.get_manifest()
.   File "/usr/lib/python2.7/dist-packages/duplicity/collections.py", line 250, in get_manifest
.     return self.get_local_manifest()
.   File "/usr/lib/python2.7/dist-packages/duplicity/collections.py", line 222, in get_local_manifest
.     manifest_buffer = self.local_manifest_path.get_data()
.   File "/usr/lib/python2.7/dist-packages/duplicity/path.py", line 178, in get_data
.     fin = self.open("rb")
.   File "/usr/lib/python2.7/dist-packages/duplicity/path.py", line 566, in open
.     result = open(self.name, mode)
. IOError: [Errno 13] Permission denied: '/var/ALF_BACKUP/duplicity/cardinal/cache/851ae8022a8438d2a54208d38005896b/duplicity-inc.20210908T230004Z.to.20210908T230037Z.manifest'
. 

2021-09-13-11:02:33 PM - [BART-Loglevel4] Running command - /usr/bin/duplicity remove-older-than 12M -v4 --log-file=/var/ALF_BACKUP/cardinal/logs/alfresco-bart-2021-09-13.log --archive-dir=/var/ALF_BACKUP/duplicity/cardinal/cache/ --force file:///var/BACKUPS/ALF_BACKUP/cardinal/data_backup/cs
Local and Remote metadata are synchronized, no sync needed.
NOTICE 1
. Local and Remote metadata are synchronized, no sync needed.

Last full backup date: Fri Aug  6 16:23:14 2021
NOTICE 1
. Last full backup date: Fri Aug  6 16:23:14 2021

No old backup sets found, nothing deleted.
NOTICE 1
. No old backup sets found, nothing deleted.

2021-09-13-11:02:35 PM - [BART-Loglevel4] Running command - /usr/bin/duplicity remove-all-but-n-full 6 -v4 --log-file=/var/ALF_BACKUP/cardinal/logs/alfresco-bart-2021-09-13.log --archive-dir=/var/ALF_BACKUP/duplicity/cardinal/cache/ --force file:///var/BACKUPS/ALF_BACKUP/cardinal/data_backup/cs
Local and Remote metadata are synchronized, no sync needed.
NOTICE 1
. Local and Remote metadata are synchronized, no sync needed.

Last full backup date: Fri Aug  6 16:23:14 2021
NOTICE 1
. Last full backup date: Fri Aug  6 16:23:14 2021

No old backup sets found, nothing deleted.
NOTICE 1
. No old backup sets found, nothing deleted.

2021-09-13-11:02:37 PM - [BART-Loglevel4] Running command - /usr/bin/duplicity remove-older-than 12M -v4 --log-file=/var/ALF_BACKUP/cardinal/logs/alfresco-bart-2021-09-13.log --archive-dir=/var/ALF_BACKUP/duplicity/cardinal/cache/ --force file:///var/BACKUPS/ALF_BACKUP/cardinal/data_backup/files
Local and Remote metadata are synchronized, no sync needed.
NOTICE 1
. Local and Remote metadata are synchronized, no sync needed.

Traceback (most recent call last):
  File "/usr/bin/duplicity", line 1553, in <module>
    with_tempdir(main)
  File "/usr/bin/duplicity", line 1547, in with_tempdir
    fn()
  File "/usr/bin/duplicity", line 1398, in main
    do_backup(action)
  File "/usr/bin/duplicity", line 1423, in do_backup
    globals.archive_dir).set_values()
  File "/usr/lib/python2.7/dist-packages/duplicity/collections.py", line 710, in set_values
    self.get_backup_chains(partials + backend_filename_list)
  File "/usr/lib/python2.7/dist-packages/duplicity/collections.py", line 836, in get_backup_chains
    add_to_sets(f)
  File "/usr/lib/python2.7/dist-packages/duplicity/collections.py", line 824, in add_to_sets
    if set.add_filename(filename):
  File "/usr/lib/python2.7/dist-packages/duplicity/collections.py", line 101, in add_filename
    self.set_manifest(filename)
  File "/usr/lib/python2.7/dist-packages/duplicity/collections.py", line 148, in set_manifest
    self.set_files_changed()
  File "/usr/lib/python2.7/dist-packages/duplicity/collections.py", line 128, in set_files_changed
    mf = self.get_manifest()
  File "/usr/lib/python2.7/dist-packages/duplicity/collections.py", line 250, in get_manifest
    return self.get_local_manifest()
  File "/usr/lib/python2.7/dist-packages/duplicity/collections.py", line 222, in get_local_manifest
    manifest_buffer = self.local_manifest_path.get_data()
  File "/usr/lib/python2.7/dist-packages/duplicity/path.py", line 178, in get_data
    fin = self.open("rb")
  File "/usr/lib/python2.7/dist-packages/duplicity/path.py", line 566, in open
    result = open(self.name, mode)
IOError: [Errno 13] Permission denied: '/var/ALF_BACKUP/duplicity/cardinal/cache/8631ebd4b7614287d4db1bbfe9c47d1d/duplicity-inc.20210907T230228Z.to.20210908T230040Z.manifest'

ERROR 30 IOError
. Traceback (most recent call last):
.   File "/usr/bin/duplicity", line 1553, in <module>
.     with_tempdir(main)
.   File "/usr/bin/duplicity", line 1547, in with_tempdir
.     fn()
.   File "/usr/bin/duplicity", line 1398, in main
.     do_backup(action)
.   File "/usr/bin/duplicity", line 1423, in do_backup
.     globals.archive_dir).set_values()
.   File "/usr/lib/python2.7/dist-packages/duplicity/collections.py", line 710, in set_values
.     self.get_backup_chains(partials + backend_filename_list)
.   File "/usr/lib/python2.7/dist-packages/duplicity/collections.py", line 836, in get_backup_chains
.     add_to_sets(f)
.   File "/usr/lib/python2.7/dist-packages/duplicity/collections.py", line 824, in add_to_sets
.     if set.add_filename(filename):
.   File "/usr/lib/python2.7/dist-packages/duplicity/collections.py", line 101, in add_filename
.     self.set_manifest(filename)
.   File "/usr/lib/python2.7/dist-packages/duplicity/collections.py", line 148, in set_manifest
.     self.set_files_changed()
.   File "/usr/lib/python2.7/dist-packages/duplicity/collections.py", line 128, in set_files_changed
.     mf = self.get_manifest()
.   File "/usr/lib/python2.7/dist-packages/duplicity/collections.py", line 250, in get_manifest
.     return self.get_local_manifest()
.   File "/usr/lib/python2.7/dist-packages/duplicity/collections.py", line 222, in get_local_manifest
.     manifest_buffer = self.local_manifest_path.get_data()
.   File "/usr/lib/python2.7/dist-packages/duplicity/path.py", line 178, in get_data
.     fin = self.open("rb")
.   File "/usr/lib/python2.7/dist-packages/duplicity/path.py", line 566, in open
.     result = open(self.name, mode)
. IOError: [Errno 13] Permission denied: '/var/ALF_BACKUP/duplicity/cardinal/cache/8631ebd4b7614287d4db1bbfe9c47d1d/duplicity-inc.20210907T230228Z.to.20210908T230040Z.manifest'
. 

2021-09-13-11:02:39 PM - [BART-Loglevel4] Running command - /usr/bin/duplicity remove-all-but-n-full 6 -v4 --log-file=/var/ALF_BACKUP/cardinal/logs/alfresco-bart-2021-09-13.log --archive-dir=/var/ALF_BACKUP/duplicity/cardinal/cache/ --force file:///var/BACKUPS/ALF_BACKUP/cardinal/data_backup/files
Local and Remote metadata are synchronized, no sync needed.
NOTICE 1
. Local and Remote metadata are synchronized, no sync needed.

Traceback (most recent call last):
  File "/usr/bin/duplicity", line 1553, in <module>
    with_tempdir(main)
  File "/usr/bin/duplicity", line 1547, in with_tempdir
    fn()
  File "/usr/bin/duplicity", line 1398, in main
    do_backup(action)
  File "/usr/bin/duplicity", line 1423, in do_backup
    globals.archive_dir).set_values()
  File "/usr/lib/python2.7/dist-packages/duplicity/collections.py", line 710, in set_values
    self.get_backup_chains(partials + backend_filename_list)
  File "/usr/lib/python2.7/dist-packages/duplicity/collections.py", line 836, in get_backup_chains
    add_to_sets(f)
  File "/usr/lib/python2.7/dist-packages/duplicity/collections.py", line 824, in add_to_sets
    if set.add_filename(filename):
  File "/usr/lib/python2.7/dist-packages/duplicity/collections.py", line 101, in add_filename
    self.set_manifest(filename)
  File "/usr/lib/python2.7/dist-packages/duplicity/collections.py", line 148, in set_manifest
    self.set_files_changed()
  File "/usr/lib/python2.7/dist-packages/duplicity/collections.py", line 128, in set_files_changed
    mf = self.get_manifest()
  File "/usr/lib/python2.7/dist-packages/duplicity/collections.py", line 250, in get_manifest
    return self.get_local_manifest()
  File "/usr/lib/python2.7/dist-packages/duplicity/collections.py", line 222, in get_local_manifest
    manifest_buffer = self.local_manifest_path.get_data()
  File "/usr/lib/python2.7/dist-packages/duplicity/path.py", line 178, in get_data
    fin = self.open("rb")
  File "/usr/lib/python2.7/dist-packages/duplicity/path.py", line 566, in open
    result = open(self.name, mode)
IOError: [Errno 13] Permission denied: '/var/ALF_BACKUP/duplicity/cardinal/cache/8631ebd4b7614287d4db1bbfe9c47d1d/duplicity-inc.20210907T230228Z.to.20210908T230040Z.manifest'

ERROR 30 IOError
. Traceback (most recent call last):
.   File "/usr/bin/duplicity", line 1553, in <module>
.     with_tempdir(main)
.   File "/usr/bin/duplicity", line 1547, in with_tempdir
.     fn()
.   File "/usr/bin/duplicity", line 1398, in main
.     do_backup(action)
.   File "/usr/bin/duplicity", line 1423, in do_backup
.     globals.archive_dir).set_values()
.   File "/usr/lib/python2.7/dist-packages/duplicity/collections.py", line 710, in set_values
.     self.get_backup_chains(partials + backend_filename_list)
.   File "/usr/lib/python2.7/dist-packages/duplicity/collections.py", line 836, in get_backup_chains
.     add_to_sets(f)
.   File "/usr/lib/python2.7/dist-packages/duplicity/collections.py", line 824, in add_to_sets
.     if set.add_filename(filename):
.   File "/usr/lib/python2.7/dist-packages/duplicity/collections.py", line 101, in add_filename
.     self.set_manifest(filename)
.   File "/usr/lib/python2.7/dist-packages/duplicity/collections.py", line 148, in set_manifest
.     self.set_files_changed()
.   File "/usr/lib/python2.7/dist-packages/duplicity/collections.py", line 128, in set_files_changed
.     mf = self.get_manifest()
.   File "/usr/lib/python2.7/dist-packages/duplicity/collections.py", line 250, in get_manifest
.     return self.get_local_manifest()
.   File "/usr/lib/python2.7/dist-packages/duplicity/collections.py", line 222, in get_local_manifest
.     manifest_buffer = self.local_manifest_path.get_data()
.   File "/usr/lib/python2.7/dist-packages/duplicity/path.py", line 178, in get_data
.     fin = self.open("rb")
.   File "/usr/lib/python2.7/dist-packages/duplicity/path.py", line 566, in open
.     result = open(self.name, mode)
. IOError: [Errno 13] Permission denied: '/var/ALF_BACKUP/duplicity/cardinal/cache/8631ebd4b7614287d4db1bbfe9c47d1d/duplicity-inc.20210907T230228Z.to.20210908T230040Z.manifest'
. 

2021-09-13-11:02:41 PM - [BART-Loglevel4] Maintenance commands DONE!
